INFO 2024-03-15 23:36:41,593 autoreload 15904 14296 Watching for file changes with StatReloader
INFO 2024-03-15 23:39:10,608 autoreload 16572 8560 Watching for file changes with StatReloader
INFO 2024-03-15 23:39:38,077 autoreload 16572 8560 C:\Users\dmitr\OneDrive\Рабочий стол\Django_hw2\modelsapp\modelsapp\settings.py changed, reloading.
INFO 2024-03-15 23:39:38,423 autoreload 15608 15440 Watching for file changes with StatReloader
INFO 2024-03-15 23:39:39,626 autoreload 15608 15440 C:\Users\dmitr\OneDrive\Рабочий стол\Django_hw2\modelsapp\modelsapp\settings.py changed, reloading.
INFO 2024-03-15 23:39:39,997 autoreload 15464 15288 Watching for file changes with StatReloader
INFO 2024-03-15 23:40:16,605 autoreload 15464 15288 C:\Users\dmitr\OneDrive\Рабочий стол\Django_hw2\modelsapp\modapp\models.py changed, reloading.
INFO 2024-03-15 23:40:57,593 autoreload 15948 10184 Watching for file changes with StatReloader
INFO 2024-03-16 00:18:02,429 autoreload 11860 13752 Watching for file changes with StatReloader
INFO 2024-03-16 00:21:06,686 autoreload 11860 13752 C:\Users\dmitr\OneDrive\Рабочий стол\Django_hw2\modelsapp\modapp\models.py changed, reloading.
INFO 2024-03-16 00:21:07,062 autoreload 10172 14452 Watching for file changes with StatReloader
INFO 2024-03-16 00:33:03,243 autoreload 10172 14452 C:\Users\dmitr\OneDrive\Рабочий стол\Django_hw2\modelsapp\modapp\models.py changed, reloading.
INFO 2024-03-16 00:33:03,557 autoreload 15624 12632 Watching for file changes with StatReloader
INFO 2024-03-16 00:33:26,005 autoreload 15624 12632 C:\Users\dmitr\OneDrive\Рабочий стол\Django_hw2\modelsapp\modapp\models.py changed, reloading.
INFO 2024-03-16 00:33:26,323 autoreload 6836 14568 Watching for file changes with StatReloader
INFO 2024-03-16 00:40:25,297 autoreload 6836 14568 C:\Users\dmitr\OneDrive\Рабочий стол\Django_hw2\modelsapp\modapp\models.py changed, reloading.
INFO 2024-03-16 00:40:25,637 autoreload 5252 14464 Watching for file changes with StatReloader
INFO 2024-03-16 00:40:32,909 autoreload 12696 5532 Watching for file changes with StatReloader
INFO 2024-03-16 00:46:04,412 autoreload 12696 5532 C:\Users\dmitr\OneDrive\Рабочий стол\Django_hw2\modelsapp\modapp\models.py changed, reloading.
INFO 2024-03-16 00:46:04,769 autoreload 4620 3524 Watching for file changes with StatReloader
INFO 2024-03-16 00:46:59,577 autoreload 4620 3524 C:\Users\dmitr\OneDrive\Рабочий стол\Django_hw2\modelsapp\modapp\models.py changed, reloading.
INFO 2024-03-16 00:46:59,888 autoreload 1296 8428 Watching for file changes with StatReloader
INFO 2024-03-16 00:48:14,928 autoreload 1296 8428 C:\Users\dmitr\OneDrive\Рабочий стол\Django_hw2\modelsapp\modapp\models.py changed, reloading.
INFO 2024-03-16 00:48:15,246 autoreload 14000 17044 Watching for file changes with StatReloader
INFO 2024-03-16 00:48:48,823 autoreload 14000 17044 C:\Users\dmitr\OneDrive\Рабочий стол\Django_hw2\modelsapp\modapp\models.py changed, reloading.
INFO 2024-03-16 00:48:54,828 autoreload 5908 14836 Watching for file changes with StatReloader
INFO 2024-03-16 00:57:28,832 autoreload 5908 14836 C:\Users\dmitr\OneDrive\Рабочий стол\Django_hw2\modelsapp\modelsapp\urls.py changed, reloading.
INFO 2024-03-16 00:57:29,189 autoreload 16948 6836 Watching for file changes with StatReloader
INFO 2024-03-16 00:57:33,500 autoreload 16948 6836 C:\Users\dmitr\OneDrive\Рабочий стол\Django_hw2\modelsapp\modelsapp\urls.py changed, reloading.
INFO 2024-03-16 00:57:33,839 autoreload 15392 6464 Watching for file changes with StatReloader
INFO 2024-03-22 20:12:35,105 autoreload 9940 2828 Watching for file changes with StatReloader
INFO 2024-03-22 20:13:31,218 autoreload 8344 7744 Watching for file changes with StatReloader
ERROR 2024-03-22 20:13:40,397 exception 8344 14540 Invalid HTTP_HOST header: '127.0.0.1:8000'. You may need to add '127.0.0.1' to ALLOWED_HOSTS.
Traceback (most recent call last):
  File "C:\Users\dmitr\OneDrive\Рабочий стол\Django\Django_hw2\venv\lib\site-packages\django\core\handlers\exception.py", line 55, in inner
    response = get_response(request)
  File "C:\Users\dmitr\OneDrive\Рабочий стол\Django\Django_hw2\venv\lib\site-packages\django\utils\deprecation.py", line 133, in __call__
    response = self.process_request(request)
  File "C:\Users\dmitr\OneDrive\Рабочий стол\Django\Django_hw2\venv\lib\site-packages\django\middleware\common.py", line 48, in process_request
    host = request.get_host()
  File "C:\Users\dmitr\OneDrive\Рабочий стол\Django\Django_hw2\venv\lib\site-packages\django\http\request.py", line 151, in get_host
    raise DisallowedHost(msg)
django.core.exceptions.DisallowedHost: Invalid HTTP_HOST header: '127.0.0.1:8000'. You may need to add '127.0.0.1' to ALLOWED_HOSTS.
WARNING 2024-03-22 20:13:40,501 log 8344 14540 Bad Request: /
WARNING 2024-03-22 20:13:40,501 basehttp 8344 14540 "GET / HTTP/1.1" 400 71345
ERROR 2024-03-22 20:13:40,528 exception 8344 14460 Invalid HTTP_HOST header: '127.0.0.1:8000'. You may need to add '127.0.0.1' to ALLOWED_HOSTS.
Traceback (most recent call last):
  File "C:\Users\dmitr\OneDrive\Рабочий стол\Django\Django_hw2\venv\lib\site-packages\django\core\handlers\exception.py", line 55, in inner
    response = get_response(request)
  File "C:\Users\dmitr\OneDrive\Рабочий стол\Django\Django_hw2\venv\lib\site-packages\django\utils\deprecation.py", line 133, in __call__
    response = self.process_request(request)
  File "C:\Users\dmitr\OneDrive\Рабочий стол\Django\Django_hw2\venv\lib\site-packages\django\middleware\common.py", line 48, in process_request
    host = request.get_host()
  File "C:\Users\dmitr\OneDrive\Рабочий стол\Django\Django_hw2\venv\lib\site-packages\django\http\request.py", line 151, in get_host
    raise DisallowedHost(msg)
django.core.exceptions.DisallowedHost: Invalid HTTP_HOST header: '127.0.0.1:8000'. You may need to add '127.0.0.1' to ALLOWED_HOSTS.
WARNING 2024-03-22 20:13:40,544 log 8344 14460 Bad Request: /favicon.ico
WARNING 2024-03-22 20:13:40,544 basehttp 8344 14460 "GET /favicon.ico HTTP/1.1" 400 69902
ERROR 2024-03-22 20:13:40,670 exception 8344 15156 Invalid HTTP_HOST header: '127.0.0.1:8000'. You may need to add '127.0.0.1' to ALLOWED_HOSTS.
Traceback (most recent call last):
  File "C:\Users\dmitr\OneDrive\Рабочий стол\Django\Django_hw2\venv\lib\site-packages\django\core\handlers\exception.py", line 55, in inner
    response = get_response(request)
  File "C:\Users\dmitr\OneDrive\Рабочий стол\Django\Django_hw2\venv\lib\site-packages\django\utils\deprecation.py", line 133, in __call__
    response = self.process_request(request)
  File "C:\Users\dmitr\OneDrive\Рабочий стол\Django\Django_hw2\venv\lib\site-packages\django\middleware\common.py", line 48, in process_request
    host = request.get_host()
  File "C:\Users\dmitr\OneDrive\Рабочий стол\Django\Django_hw2\venv\lib\site-packages\django\http\request.py", line 151, in get_host
    raise DisallowedHost(msg)
django.core.exceptions.DisallowedHost: Invalid HTTP_HOST header: '127.0.0.1:8000'. You may need to add '127.0.0.1' to ALLOWED_HOSTS.
WARNING 2024-03-22 20:13:40,689 log 8344 15156 Bad Request: /favicon.ico
WARNING 2024-03-22 20:13:40,690 basehttp 8344 15156 "GET /favicon.ico HTTP/1.1" 400 71270
ERROR 2024-03-22 20:13:53,344 exception 8344 5108 Invalid HTTP_HOST header: '127.0.0.1:8000'. You may need to add '127.0.0.1' to ALLOWED_HOSTS.
Traceback (most recent call last):
  File "C:\Users\dmitr\OneDrive\Рабочий стол\Django\Django_hw2\venv\lib\site-packages\django\core\handlers\exception.py", line 55, in inner
    response = get_response(request)
  File "C:\Users\dmitr\OneDrive\Рабочий стол\Django\Django_hw2\venv\lib\site-packages\django\utils\deprecation.py", line 133, in __call__
    response = self.process_request(request)
  File "C:\Users\dmitr\OneDrive\Рабочий стол\Django\Django_hw2\venv\lib\site-packages\django\middleware\common.py", line 48, in process_request
    host = request.get_host()
  File "C:\Users\dmitr\OneDrive\Рабочий стол\Django\Django_hw2\venv\lib\site-packages\django\http\request.py", line 151, in get_host
    raise DisallowedHost(msg)
django.core.exceptions.DisallowedHost: Invalid HTTP_HOST header: '127.0.0.1:8000'. You may need to add '127.0.0.1' to ALLOWED_HOSTS.
WARNING 2024-03-22 20:13:53,362 log 8344 5108 Bad Request: /favicon.ico
WARNING 2024-03-22 20:13:53,362 basehttp 8344 5108 "GET /favicon.ico HTTP/1.1" 400 69902
INFO 2024-03-22 21:47:20,820 autoreload 13036 4660 Watching for file changes with StatReloader
ERROR 2024-03-22 21:47:22,582 exception 13036 7824 Invalid HTTP_HOST header: '127.0.0.1:8000'. You may need to add '127.0.0.1' to ALLOWED_HOSTS.
Traceback (most recent call last):
  File "C:\Users\dmitr\OneDrive\Рабочий стол\Django\Django_hw2\venv\lib\site-packages\django\core\handlers\exception.py", line 55, in inner
    response = get_response(request)
  File "C:\Users\dmitr\OneDrive\Рабочий стол\Django\Django_hw2\venv\lib\site-packages\django\utils\deprecation.py", line 133, in __call__
    response = self.process_request(request)
  File "C:\Users\dmitr\OneDrive\Рабочий стол\Django\Django_hw2\venv\lib\site-packages\django\middleware\common.py", line 48, in process_request
    host = request.get_host()
  File "C:\Users\dmitr\OneDrive\Рабочий стол\Django\Django_hw2\venv\lib\site-packages\django\http\request.py", line 151, in get_host
    raise DisallowedHost(msg)
django.core.exceptions.DisallowedHost: Invalid HTTP_HOST header: '127.0.0.1:8000'. You may need to add '127.0.0.1' to ALLOWED_HOSTS.
WARNING 2024-03-22 21:47:22,645 log 13036 7824 Bad Request: /
WARNING 2024-03-22 21:47:22,645 basehttp 13036 7824 "GET / HTTP/1.1" 400 71345
ERROR 2024-03-22 21:47:22,865 exception 13036 2028 Invalid HTTP_HOST header: '127.0.0.1:8000'. You may need to add '127.0.0.1' to ALLOWED_HOSTS.
Traceback (most recent call last):
  File "C:\Users\dmitr\OneDrive\Рабочий стол\Django\Django_hw2\venv\lib\site-packages\django\core\handlers\exception.py", line 55, in inner
    response = get_response(request)
  File "C:\Users\dmitr\OneDrive\Рабочий стол\Django\Django_hw2\venv\lib\site-packages\django\utils\deprecation.py", line 133, in __call__
    response = self.process_request(request)
  File "C:\Users\dmitr\OneDrive\Рабочий стол\Django\Django_hw2\venv\lib\site-packages\django\middleware\common.py", line 48, in process_request
    host = request.get_host()
  File "C:\Users\dmitr\OneDrive\Рабочий стол\Django\Django_hw2\venv\lib\site-packages\django\http\request.py", line 151, in get_host
    raise DisallowedHost(msg)
django.core.exceptions.DisallowedHost: Invalid HTTP_HOST header: '127.0.0.1:8000'. You may need to add '127.0.0.1' to ALLOWED_HOSTS.
WARNING 2024-03-22 21:47:22,894 log 13036 2028 Bad Request: /favicon.ico
WARNING 2024-03-22 21:47:22,895 basehttp 13036 2028 "GET /favicon.ico HTTP/1.1" 400 71270
ERROR 2024-03-22 21:47:29,343 exception 13036 15696 Invalid HTTP_HOST header: '127.0.0.1:8000'. You may need to add '127.0.0.1' to ALLOWED_HOSTS.
Traceback (most recent call last):
  File "C:\Users\dmitr\OneDrive\Рабочий стол\Django\Django_hw2\venv\lib\site-packages\django\core\handlers\exception.py", line 55, in inner
    response = get_response(request)
  File "C:\Users\dmitr\OneDrive\Рабочий стол\Django\Django_hw2\venv\lib\site-packages\django\utils\deprecation.py", line 133, in __call__
    response = self.process_request(request)
  File "C:\Users\dmitr\OneDrive\Рабочий стол\Django\Django_hw2\venv\lib\site-packages\django\middleware\common.py", line 48, in process_request
    host = request.get_host()
  File "C:\Users\dmitr\OneDrive\Рабочий стол\Django\Django_hw2\venv\lib\site-packages\django\http\request.py", line 151, in get_host
    raise DisallowedHost(msg)
django.core.exceptions.DisallowedHost: Invalid HTTP_HOST header: '127.0.0.1:8000'. You may need to add '127.0.0.1' to ALLOWED_HOSTS.
WARNING 2024-03-22 21:47:29,360 log 13036 15696 Bad Request: /hw2
WARNING 2024-03-22 21:47:29,361 basehttp 13036 15696 "GET /hw2 HTTP/1.1" 400 71378
ERROR 2024-03-22 21:47:29,447 exception 13036 5680 Invalid HTTP_HOST header: '127.0.0.1:8000'. You may need to add '127.0.0.1' to ALLOWED_HOSTS.
Traceback (most recent call last):
  File "C:\Users\dmitr\OneDrive\Рабочий стол\Django\Django_hw2\venv\lib\site-packages\django\core\handlers\exception.py", line 55, in inner
    response = get_response(request)
  File "C:\Users\dmitr\OneDrive\Рабочий стол\Django\Django_hw2\venv\lib\site-packages\django\utils\deprecation.py", line 133, in __call__
    response = self.process_request(request)
  File "C:\Users\dmitr\OneDrive\Рабочий стол\Django\Django_hw2\venv\lib\site-packages\django\middleware\common.py", line 48, in process_request
    host = request.get_host()
  File "C:\Users\dmitr\OneDrive\Рабочий стол\Django\Django_hw2\venv\lib\site-packages\django\http\request.py", line 151, in get_host
    raise DisallowedHost(msg)
django.core.exceptions.DisallowedHost: Invalid HTTP_HOST header: '127.0.0.1:8000'. You may need to add '127.0.0.1' to ALLOWED_HOSTS.
WARNING 2024-03-22 21:47:29,464 log 13036 5680 Bad Request: /favicon.ico
WARNING 2024-03-22 21:47:29,464 basehttp 13036 5680 "GET /favicon.ico HTTP/1.1" 400 71273
ERROR 2024-03-22 21:48:00,084 exception 13036 8912 Invalid HTTP_HOST header: '127.0.0.1:8000'. You may need to add '127.0.0.1' to ALLOWED_HOSTS.
Traceback (most recent call last):
  File "C:\Users\dmitr\OneDrive\Рабочий стол\Django\Django_hw2\venv\lib\site-packages\django\core\handlers\exception.py", line 55, in inner
    response = get_response(request)
  File "C:\Users\dmitr\OneDrive\Рабочий стол\Django\Django_hw2\venv\lib\site-packages\django\utils\deprecation.py", line 133, in __call__
    response = self.process_request(request)
  File "C:\Users\dmitr\OneDrive\Рабочий стол\Django\Django_hw2\venv\lib\site-packages\django\middleware\common.py", line 48, in process_request
    host = request.get_host()
  File "C:\Users\dmitr\OneDrive\Рабочий стол\Django\Django_hw2\venv\lib\site-packages\django\http\request.py", line 151, in get_host
    raise DisallowedHost(msg)
django.core.exceptions.DisallowedHost: Invalid HTTP_HOST header: '127.0.0.1:8000'. You may need to add '127.0.0.1' to ALLOWED_HOSTS.
WARNING 2024-03-22 21:48:00,101 log 13036 8912 Bad Request: /index/
WARNING 2024-03-22 21:48:00,101 basehttp 13036 8912 "GET /index/ HTTP/1.1" 400 71685
ERROR 2024-03-22 21:48:01,408 exception 13036 13468 Invalid HTTP_HOST header: '127.0.0.1:8000'. You may need to add '127.0.0.1' to ALLOWED_HOSTS.
Traceback (most recent call last):
  File "C:\Users\dmitr\OneDrive\Рабочий стол\Django\Django_hw2\venv\lib\site-packages\django\core\handlers\exception.py", line 55, in inner
    response = get_response(request)
  File "C:\Users\dmitr\OneDrive\Рабочий стол\Django\Django_hw2\venv\lib\site-packages\django\utils\deprecation.py", line 133, in __call__
    response = self.process_request(request)
  File "C:\Users\dmitr\OneDrive\Рабочий стол\Django\Django_hw2\venv\lib\site-packages\django\middleware\common.py", line 48, in process_request
    host = request.get_host()
  File "C:\Users\dmitr\OneDrive\Рабочий стол\Django\Django_hw2\venv\lib\site-packages\django\http\request.py", line 151, in get_host
    raise DisallowedHost(msg)
django.core.exceptions.DisallowedHost: Invalid HTTP_HOST header: '127.0.0.1:8000'. You may need to add '127.0.0.1' to ALLOWED_HOSTS.
WARNING 2024-03-22 21:48:01,424 log 13036 13468 Bad Request: /index/
WARNING 2024-03-22 21:48:01,425 basehttp 13036 13468 "GET /index/ HTTP/1.1" 400 71411
ERROR 2024-03-22 21:48:01,519 exception 13036 6228 Invalid HTTP_HOST header: '127.0.0.1:8000'. You may need to add '127.0.0.1' to ALLOWED_HOSTS.
Traceback (most recent call last):
  File "C:\Users\dmitr\OneDrive\Рабочий стол\Django\Django_hw2\venv\lib\site-packages\django\core\handlers\exception.py", line 55, in inner
    response = get_response(request)
  File "C:\Users\dmitr\OneDrive\Рабочий стол\Django\Django_hw2\venv\lib\site-packages\django\utils\deprecation.py", line 133, in __call__
    response = self.process_request(request)
  File "C:\Users\dmitr\OneDrive\Рабочий стол\Django\Django_hw2\venv\lib\site-packages\django\middleware\common.py", line 48, in process_request
    host = request.get_host()
  File "C:\Users\dmitr\OneDrive\Рабочий стол\Django\Django_hw2\venv\lib\site-packages\django\http\request.py", line 151, in get_host
    raise DisallowedHost(msg)
django.core.exceptions.DisallowedHost: Invalid HTTP_HOST header: '127.0.0.1:8000'. You may need to add '127.0.0.1' to ALLOWED_HOSTS.
WARNING 2024-03-22 21:48:01,536 log 13036 6228 Bad Request: /favicon.ico
WARNING 2024-03-22 21:48:01,536 basehttp 13036 6228 "GET /favicon.ico HTTP/1.1" 400 71276
ERROR 2024-03-22 21:48:19,865 exception 13036 15884 Invalid HTTP_HOST header: '127.0.0.1:8000'. You may need to add '127.0.0.1' to ALLOWED_HOSTS.
Traceback (most recent call last):
  File "C:\Users\dmitr\OneDrive\Рабочий стол\Django\Django_hw2\venv\lib\site-packages\django\core\handlers\exception.py", line 55, in inner
    response = get_response(request)
  File "C:\Users\dmitr\OneDrive\Рабочий стол\Django\Django_hw2\venv\lib\site-packages\django\utils\deprecation.py", line 133, in __call__
    response = self.process_request(request)
  File "C:\Users\dmitr\OneDrive\Рабочий стол\Django\Django_hw2\venv\lib\site-packages\django\middleware\common.py", line 48, in process_request
    host = request.get_host()
  File "C:\Users\dmitr\OneDrive\Рабочий стол\Django\Django_hw2\venv\lib\site-packages\django\http\request.py", line 151, in get_host
    raise DisallowedHost(msg)
django.core.exceptions.DisallowedHost: Invalid HTTP_HOST header: '127.0.0.1:8000'. You may need to add '127.0.0.1' to ALLOWED_HOSTS.
WARNING 2024-03-22 21:48:19,882 log 13036 15884 Bad Request: /index/
WARNING 2024-03-22 21:48:19,882 basehttp 13036 15884 "GET /index/ HTTP/1.1" 400 71548
ERROR 2024-03-22 21:48:19,954 exception 13036 15808 Invalid HTTP_HOST header: '127.0.0.1:8000'. You may need to add '127.0.0.1' to ALLOWED_HOSTS.
Traceback (most recent call last):
  File "C:\Users\dmitr\OneDrive\Рабочий стол\Django\Django_hw2\venv\lib\site-packages\django\core\handlers\exception.py", line 55, in inner
    response = get_response(request)
  File "C:\Users\dmitr\OneDrive\Рабочий стол\Django\Django_hw2\venv\lib\site-packages\django\utils\deprecation.py", line 133, in __call__
    response = self.process_request(request)
  File "C:\Users\dmitr\OneDrive\Рабочий стол\Django\Django_hw2\venv\lib\site-packages\django\middleware\common.py", line 48, in process_request
    host = request.get_host()
  File "C:\Users\dmitr\OneDrive\Рабочий стол\Django\Django_hw2\venv\lib\site-packages\django\http\request.py", line 151, in get_host
    raise DisallowedHost(msg)
django.core.exceptions.DisallowedHost: Invalid HTTP_HOST header: '127.0.0.1:8000'. You may need to add '127.0.0.1' to ALLOWED_HOSTS.
WARNING 2024-03-22 21:48:19,969 log 13036 15808 Bad Request: /favicon.ico
WARNING 2024-03-22 21:48:19,970 basehttp 13036 15808 "GET /favicon.ico HTTP/1.1" 400 71276
INFO 2024-03-22 21:48:56,602 autoreload 13036 4660 C:\Users\dmitr\OneDrive\Рабочий стол\Django\Django_hw2\modelsapp\modelsapp\settings.py changed, reloading.
INFO 2024-03-22 21:49:04,574 autoreload 16212 16224 Watching for file changes with StatReloader
WARNING 2024-03-22 21:49:05,983 log 16212 6248 Not Found: /
WARNING 2024-03-22 21:49:05,984 basehttp 16212 6248 "GET / HTTP/1.1" 404 2166
WARNING 2024-03-22 21:49:06,105 log 16212 6248 Not Found: /favicon.ico
WARNING 2024-03-22 21:49:06,106 basehttp 16212 6248 "GET /favicon.ico HTTP/1.1" 404 2217
WARNING 2024-03-22 21:49:09,958 log 16212 6248 Not Found: /index/
WARNING 2024-03-22 21:49:09,958 basehttp 16212 6248 "GET /index/ HTTP/1.1" 404 2202
WARNING 2024-03-22 21:49:14,313 log 16212 6248 Not Found: /index/
WARNING 2024-03-22 21:49:14,313 basehttp 16212 6248 "GET /index/ HTTP/1.1" 404 2202
WARNING 2024-03-22 21:49:20,023 log 16212 6248 Not Found: /index/
WARNING 2024-03-22 21:49:20,023 basehttp 16212 6248 "GET /index/ HTTP/1.1" 404 2202
INFO 2024-03-22 21:49:22,526 basehttp 16212 6248 "GET /hw3 HTTP/1.1" 301 0
INFO 2024-03-22 21:49:22,544 basehttp 16212 10632 "GET /hw3/ HTTP/1.1" 200 736
INFO 2024-03-22 21:49:34,190 basehttp 16212 10632 "GET /hw3/index HTTP/1.1" 301 0
INFO 2024-03-22 21:49:34,203 basehttp 16212 10072 "GET /hw3/index/ HTTP/1.1" 200 736
WARNING 2024-03-22 21:49:53,425 log 16212 10072 Not Found: /hw3/user/5
WARNING 2024-03-22 21:49:53,426 basehttp 16212 10072 "GET /hw3/user/5 HTTP/1.1" 404 2865
WARNING 2024-03-22 21:49:59,320 log 16212 10072 Not Found: /hw3/user/1
WARNING 2024-03-22 21:49:59,321 basehttp 16212 10072 "GET /hw3/user/1 HTTP/1.1" 404 2865
WARNING 2024-03-22 21:50:17,875 log 16212 10072 Not Found: /hw3/user/user/3/
WARNING 2024-03-22 21:50:17,876 basehttp 16212 10072 "GET /hw3/user/user/3/ HTTP/1.1" 404 2883
INFO 2024-03-22 21:50:54,607 autoreload 16212 16224 C:\Users\dmitr\OneDrive\Рабочий стол\Django\Django_hw2\modelsapp\modapp\urls.py changed, reloading.
INFO 2024-03-22 21:50:54,966 autoreload 15948 16332 Watching for file changes with StatReloader
WARNING 2024-03-22 21:50:56,641 log 15948 13500 Not Found: /
WARNING 2024-03-22 21:50:56,641 basehttp 15948 13500 "GET / HTTP/1.1" 404 2166
INFO 2024-03-22 21:51:02,328 basehttp 15948 13500 "GET /hw3/ HTTP/1.1" 200 736
WARNING 2024-03-22 21:51:11,551 log 15948 13500 Not Found: /hw3/user/3
WARNING 2024-03-22 21:51:11,552 basehttp 15948 13500 "GET /hw3/user/3 HTTP/1.1" 404 2865
INFO 2024-03-22 21:51:29,699 basehttp 15948 13500 "GET /hw3/basket/3 HTTP/1.1" 301 0
ERROR 2024-03-22 21:51:29,756 log 15948 6464 Internal Server Error: /hw3/basket/3/
Traceback (most recent call last):
  File "C:\Users\dmitr\OneDrive\Рабочий стол\Django\Django_hw2\venv\lib\site-packages\django\core\handlers\exception.py", line 55, in inner
    response = get_response(request)
  File "C:\Users\dmitr\OneDrive\Рабочий стол\Django\Django_hw2\venv\lib\site-packages\django\core\handlers\base.py", line 204, in _get_response
    self.check_response(response, callback)
  File "C:\Users\dmitr\OneDrive\Рабочий стол\Django\Django_hw2\venv\lib\site-packages\django\core\handlers\base.py", line 332, in check_response
    raise ValueError(
ValueError: The view modapp.views.basket didn't return an HttpResponse object. It returned None instead.
ERROR 2024-03-22 21:51:29,756 basehttp 15948 6464 "GET /hw3/basket/3/ HTTP/1.1" 500 67983
INFO 2024-03-22 21:52:02,537 autoreload 15948 16332 C:\Users\dmitr\OneDrive\Рабочий стол\Django\Django_hw2\modelsapp\modapp\urls.py changed, reloading.
INFO 2024-03-22 21:52:02,897 autoreload 8972 16096 Watching for file changes with StatReloader
INFO 2024-03-22 21:53:51,522 autoreload 7144 12416 Watching for file changes with StatReloader
WARNING 2024-03-22 21:53:54,151 log 7144 7768 Not Found: /
WARNING 2024-03-22 21:53:54,152 basehttp 7144 7768 "GET / HTTP/1.1" 404 2166
INFO 2024-03-22 21:54:00,755 basehttp 7144 7768 "GET /hw3/ HTTP/1.1" 200 736
INFO 2024-03-22 21:54:07,595 basehttp 7144 7768 "GET /hw3/user/3 HTTP/1.1" 301 0
ERROR 2024-03-22 21:54:07,636 log 7144 14648 Internal Server Error: /hw3/user/3/
Traceback (most recent call last):
  File "C:\Users\dmitr\OneDrive\Рабочий стол\Django\Django_hw2\venv\lib\site-packages\django\core\handlers\exception.py", line 55, in inner
    response = get_response(request)
  File "C:\Users\dmitr\OneDrive\Рабочий стол\Django\Django_hw2\venv\lib\site-packages\django\core\handlers\base.py", line 204, in _get_response
    self.check_response(response, callback)
  File "C:\Users\dmitr\OneDrive\Рабочий стол\Django\Django_hw2\venv\lib\site-packages\django\core\handlers\base.py", line 332, in check_response
    raise ValueError(
ValueError: The view modapp.views.basket didn't return an HttpResponse object. It returned None instead.
ERROR 2024-03-22 21:54:07,637 basehttp 7144 14648 "GET /hw3/user/3/ HTTP/1.1" 500 67965
INFO 2024-03-22 22:49:41,052 autoreload 2732 6396 Watching for file changes with StatReloader
WARNING 2024-03-22 22:49:43,456 log 2732 12604 Not Found: /
WARNING 2024-03-22 22:49:43,457 basehttp 2732 12604 "GET / HTTP/1.1" 404 2166
ERROR 2024-03-22 22:49:48,485 log 2732 12604 Internal Server Error: /hw3/user/3/
Traceback (most recent call last):
  File "C:\Users\dmitr\OneDrive\Рабочий стол\Django_hw2\venv\lib\site-packages\django\core\handlers\exception.py", line 55, in inner
    response = get_response(request)
  File "C:\Users\dmitr\OneDrive\Рабочий стол\Django_hw2\venv\lib\site-packages\django\core\handlers\base.py", line 204, in _get_response
    self.check_response(response, callback)
  File "C:\Users\dmitr\OneDrive\Рабочий стол\Django_hw2\venv\lib\site-packages\django\core\handlers\base.py", line 332, in check_response
    raise ValueError(
ValueError: The view modapp.views.basket didn't return an HttpResponse object. It returned None instead.
ERROR 2024-03-22 22:49:48,485 basehttp 2732 12604 "GET /hw3/user/3/ HTTP/1.1" 500 67999
WARNING 2024-03-22 22:49:51,241 log 2732 12604 Not Found: /hw3/user/
WARNING 2024-03-22 22:49:51,242 basehttp 2732 12604 "GET /hw3/user/ HTTP/1.1" 404 2860
INFO 2024-03-22 22:49:55,016 basehttp 2732 12604 "GET /hw3/ HTTP/1.1" 200 736
INFO 2024-03-22 23:16:23,326 autoreload 16696 1168 Watching for file changes with StatReloader
WARNING 2024-03-22 23:16:26,771 log 16696 17240 Not Found: /
WARNING 2024-03-22 23:16:26,772 basehttp 16696 17240 "GET / HTTP/1.1" 404 2166
WARNING 2024-03-22 23:16:31,669 log 16696 17240 Not Found: /about/
WARNING 2024-03-22 23:16:31,670 basehttp 16696 17240 "GET /about/ HTTP/1.1" 404 2202
INFO 2024-03-22 23:16:33,518 basehttp 16696 17240 "GET /admin/ HTTP/1.1" 302 0
INFO 2024-03-22 23:16:33,541 basehttp 16696 17240 "GET /admin/login/?next=/admin/ HTTP/1.1" 200 4158
INFO 2024-03-22 23:16:33,549 basehttp 16696 17240 "GET /static/admin/css/base.css HTTP/1.1" 304 0
INFO 2024-03-22 23:16:33,553 basehttp 16696 17240 "GET /static/admin/css/nav_sidebar.css HTTP/1.1" 304 0
INFO 2024-03-22 23:16:33,553 basehttp 16696 12956 "GET /static/admin/css/dark_mode.css HTTP/1.1" 304 0
INFO 2024-03-22 23:16:33,553 basehttp 16696 14688 "GET /static/admin/css/responsive.css HTTP/1.1" 304 0
INFO 2024-03-22 23:16:33,554 basehttp 16696 14396 "GET /static/admin/js/theme.js HTTP/1.1" 304 0
INFO 2024-03-22 23:16:33,559 basehttp 16696 12956 "GET /static/admin/css/login.css HTTP/1.1" 304 0
INFO 2024-03-22 23:16:33,566 basehttp 16696 14396 "GET /static/admin/js/nav_sidebar.js HTTP/1.1" 304 0
INFO 2024-03-22 23:16:42,956 basehttp 16696 14396 "GET /hw3/ HTTP/1.1" 200 736
INFO 2024-03-22 23:16:43,259 basehttp 16696 14396 "GET /hw3/ HTTP/1.1" 200 736
INFO 2024-03-22 23:17:55,257 basehttp 16696 14396 "GET /hw3/ HTTP/1.1" 200 736
WARNING 2024-03-22 23:18:01,010 log 16696 14396 Not Found: /index/
WARNING 2024-03-22 23:18:01,010 basehttp 16696 14396 "GET /index/ HTTP/1.1" 404 2202
WARNING 2024-03-22 23:18:02,383 log 16696 14396 Not Found: /index/
WARNING 2024-03-22 23:18:02,384 basehttp 16696 14396 "GET /index/ HTTP/1.1" 404 2202
WARNING 2024-03-22 23:18:11,978 log 16696 14396 Not Found: /index/user/3
WARNING 2024-03-22 23:18:11,979 basehttp 16696 14396 "GET /index/user/3 HTTP/1.1" 404 2220
ERROR 2024-03-22 23:18:17,484 log 16696 14396 Internal Server Error: /hw3/user/3/
Traceback (most recent call last):
  File "C:\Users\dmitr\OneDrive\Рабочий стол\Django_hw2\venv\lib\site-packages\django\core\handlers\exception.py", line 55, in inner
    response = get_response(request)
  File "C:\Users\dmitr\OneDrive\Рабочий стол\Django_hw2\venv\lib\site-packages\django\core\handlers\base.py", line 204, in _get_response
    self.check_response(response, callback)
  File "C:\Users\dmitr\OneDrive\Рабочий стол\Django_hw2\venv\lib\site-packages\django\core\handlers\base.py", line 332, in check_response
    raise ValueError(
ValueError: The view modapp.views.basket didn't return an HttpResponse object. It returned None instead.
ERROR 2024-03-22 23:18:17,485 basehttp 16696 14396 "GET /hw3/user/3/ HTTP/1.1" 500 67887
WARNING 2024-03-22 23:18:41,799 log 16696 14396 Not Found: /hw3/user/3/22
WARNING 2024-03-22 23:18:41,800 basehttp 16696 14396 "GET /hw3/user/3/22 HTTP/1.1" 404 2872
ERROR 2024-03-22 23:18:55,635 log 16696 14396 Internal Server Error: /hw3/user/3/
Traceback (most recent call last):
  File "C:\Users\dmitr\OneDrive\Рабочий стол\Django_hw2\venv\lib\site-packages\django\core\handlers\exception.py", line 55, in inner
    response = get_response(request)
  File "C:\Users\dmitr\OneDrive\Рабочий стол\Django_hw2\venv\lib\site-packages\django\core\handlers\base.py", line 204, in _get_response
    self.check_response(response, callback)
  File "C:\Users\dmitr\OneDrive\Рабочий стол\Django_hw2\venv\lib\site-packages\django\core\handlers\base.py", line 332, in check_response
    raise ValueError(
ValueError: The view modapp.views.basket didn't return an HttpResponse object. It returned None instead.
ERROR 2024-03-22 23:18:55,636 basehttp 16696 14396 "GET /hw3/user/3/ HTTP/1.1" 500 68161
INFO 2024-03-22 23:18:58,742 basehttp 16696 14396 "GET /hw3/index/ HTTP/1.1" 200 736
WARNING 2024-03-22 23:19:05,876 log 16696 14396 Not Found: /hw3/index/user/3
WARNING 2024-03-22 23:19:05,876 basehttp 16696 14396 "GET /hw3/index/user/3 HTTP/1.1" 404 2881
WARNING 2024-03-22 23:19:45,280 log 16696 14396 Not Found: /hw3/user_sorted/
WARNING 2024-03-22 23:19:45,281 basehttp 16696 14396 "GET /hw3/user_sorted/ HTTP/1.1" 404 2881
WARNING 2024-03-22 23:19:48,157 log 16696 14396 Not Found: /hw3/user_sorted/3
WARNING 2024-03-22 23:19:48,157 basehttp 16696 14396 "GET /hw3/user_sorted/3 HTTP/1.1" 404 2884
INFO 2024-03-22 23:40:02,738 autoreload 2520 16092 Watching for file changes with StatReloader
WARNING 2024-03-22 23:40:04,665 log 2520 1964 Not Found: /
WARNING 2024-03-22 23:40:04,666 basehttp 2520 1964 "GET / HTTP/1.1" 404 2166
INFO 2024-03-22 23:40:12,025 basehttp 2520 1964 "GET /hw3/ HTTP/1.1" 200 736
INFO 2024-03-22 23:40:12,945 basehttp 2520 1964 "GET /hw3/ HTTP/1.1" 200 736
WARNING 2024-03-22 23:40:20,156 log 2520 1964 Not Found: /hw3/basket
WARNING 2024-03-22 23:40:20,156 basehttp 2520 1964 "GET /hw3/basket HTTP/1.1" 404 2863
WARNING 2024-03-22 23:40:23,456 log 2520 1964 Not Found: /hw3/basket/3/
WARNING 2024-03-22 23:40:23,456 basehttp 2520 1964 "GET /hw3/basket/3/ HTTP/1.1" 404 2872
WARNING 2024-03-22 23:40:25,953 log 2520 1964 Not Found: /hw3/basket/3/4
WARNING 2024-03-22 23:40:25,954 basehttp 2520 1964 "GET /hw3/basket/3/4 HTTP/1.1" 404 2875
WARNING 2024-03-22 23:40:40,441 log 2520 1964 Not Found: /hw3/basket/3/
WARNING 2024-03-22 23:40:40,442 basehttp 2520 1964 "GET /hw3/basket/3/ HTTP/1.1" 404 2872
WARNING 2024-03-22 23:40:50,511 log 2520 1964 Not Found: /hw3/basket/3/
WARNING 2024-03-22 23:40:50,511 basehttp 2520 1964 "GET /hw3/basket/3/ HTTP/1.1" 404 2872
WARNING 2024-03-22 23:40:54,821 log 2520 1964 Not Found: /hw3/user
WARNING 2024-03-22 23:40:54,821 basehttp 2520 1964 "GET /hw3/user HTTP/1.1" 404 2857
ERROR 2024-03-22 23:40:57,855 log 2520 1964 Internal Server Error: /hw3/user/3/
Traceback (most recent call last):
  File "C:\Users\dmitr\OneDrive\Рабочий стол\Django_hw2\venv\lib\site-packages\django\core\handlers\exception.py", line 55, in inner
    response = get_response(request)
  File "C:\Users\dmitr\OneDrive\Рабочий стол\Django_hw2\venv\lib\site-packages\django\core\handlers\base.py", line 204, in _get_response
    self.check_response(response, callback)
  File "C:\Users\dmitr\OneDrive\Рабочий стол\Django_hw2\venv\lib\site-packages\django\core\handlers\base.py", line 332, in check_response
    raise ValueError(
ValueError: The view modapp.views.basket didn't return an HttpResponse object. It returned None instead.
ERROR 2024-03-22 23:40:57,857 basehttp 2520 1964 "GET /hw3/user/3/ HTTP/1.1" 500 68161
ERROR 2024-03-22 23:40:58,083 log 2520 1964 Internal Server Error: /hw3/user/3/
Traceback (most recent call last):
  File "C:\Users\dmitr\OneDrive\Рабочий стол\Django_hw2\venv\lib\site-packages\django\core\handlers\exception.py", line 55, in inner
    response = get_response(request)
  File "C:\Users\dmitr\OneDrive\Рабочий стол\Django_hw2\venv\lib\site-packages\django\core\handlers\base.py", line 204, in _get_response
    self.check_response(response, callback)
  File "C:\Users\dmitr\OneDrive\Рабочий стол\Django_hw2\venv\lib\site-packages\django\core\handlers\base.py", line 332, in check_response
    raise ValueError(
ValueError: The view modapp.views.basket didn't return an HttpResponse object. It returned None instead.
ERROR 2024-03-22 23:40:58,084 basehttp 2520 1964 "GET /hw3/user/3/ HTTP/1.1" 500 67887
INFO 2024-03-22 23:43:46,610 autoreload 2520 16092 C:\Users\dmitr\OneDrive\Рабочий стол\Django_hw2\modelsapp\modapp\views.py changed, reloading.
INFO 2024-03-22 23:43:46,999 autoreload 8432 16508 Watching for file changes with StatReloader
INFO 2024-03-22 23:46:52,886 autoreload 8432 16508 C:\Users\dmitr\OneDrive\Рабочий стол\Django_hw2\modelsapp\modapp\views.py changed, reloading.
INFO 2024-03-22 23:46:53,225 autoreload 6240 5812 Watching for file changes with StatReloader
INFO 2024-03-22 23:46:56,233 basehttp 6240 11260 "GET / HTTP/1.1" 200 736
ERROR 2024-03-22 23:47:01,516 log 6240 11260 Internal Server Error: /user/3/
Traceback (most recent call last):
  File "C:\Users\dmitr\OneDrive\Рабочий стол\Django_hw2\venv\lib\site-packages\django\core\handlers\exception.py", line 55, in inner
    response = get_response(request)
  File "C:\Users\dmitr\OneDrive\Рабочий стол\Django_hw2\venv\lib\site-packages\django\core\handlers\base.py", line 204, in _get_response
    self.check_response(response, callback)
  File "C:\Users\dmitr\OneDrive\Рабочий стол\Django_hw2\venv\lib\site-packages\django\core\handlers\base.py", line 332, in check_response
    raise ValueError(
ValueError: The view modapp.views.basket didn't return an HttpResponse object. It returned None instead.
ERROR 2024-03-22 23:47:01,518 basehttp 6240 11260 "GET /user/3/ HTTP/1.1" 500 67851
WARNING 2024-03-22 23:49:21,416 log 6240 11260 Not Found: /user/3/3/3
WARNING 2024-03-22 23:49:21,416 basehttp 6240 11260 "GET /user/3/3/3 HTTP/1.1" 404 2847
WARNING 2024-03-22 23:49:27,016 log 6240 11260 Not Found: /user/3/1/1
WARNING 2024-03-22 23:49:27,017 basehttp 6240 11260 "GET /user/3/1/1 HTTP/1.1" 404 2847
WARNING 2024-03-22 23:49:29,375 log 6240 11260 Not Found: /user/3/1
WARNING 2024-03-22 23:49:29,376 basehttp 6240 11260 "GET /user/3/1 HTTP/1.1" 404 2841
ERROR 2024-03-22 23:49:34,744 log 6240 11260 Internal Server Error: /user/3/
Traceback (most recent call last):
  File "C:\Users\dmitr\OneDrive\Рабочий стол\Django_hw2\venv\lib\site-packages\django\core\handlers\exception.py", line 55, in inner
    response = get_response(request)
  File "C:\Users\dmitr\OneDrive\Рабочий стол\Django_hw2\venv\lib\site-packages\django\core\handlers\base.py", line 204, in _get_response
    self.check_response(response, callback)
  File "C:\Users\dmitr\OneDrive\Рабочий стол\Django_hw2\venv\lib\site-packages\django\core\handlers\base.py", line 332, in check_response
    raise ValueError(
ValueError: The view modapp.views.basket didn't return an HttpResponse object. It returned None instead.
ERROR 2024-03-22 23:49:34,745 basehttp 6240 11260 "GET /user/3/ HTTP/1.1" 500 67851
WARNING 2024-03-22 23:49:40,458 log 6240 11260 Not Found: /user/3/wheel
WARNING 2024-03-22 23:49:40,458 basehttp 6240 11260 "GET /user/3/wheel HTTP/1.1" 404 2853
WARNING 2024-03-22 23:49:49,571 log 6240 11260 Not Found: /user/1/1/1
WARNING 2024-03-22 23:49:49,571 basehttp 6240 11260 "GET /user/1/1/1 HTTP/1.1" 404 2847
WARNING 2024-03-22 23:49:58,476 log 6240 11260 Not Found: /user/
WARNING 2024-03-22 23:49:58,476 basehttp 6240 11260 "GET /user/ HTTP/1.1" 404 2832
ERROR 2024-03-22 23:50:03,412 log 6240 11260 Internal Server Error: /user/2/
Traceback (most recent call last):
  File "C:\Users\dmitr\OneDrive\Рабочий стол\Django_hw2\venv\lib\site-packages\django\core\handlers\exception.py", line 55, in inner
    response = get_response(request)
  File "C:\Users\dmitr\OneDrive\Рабочий стол\Django_hw2\venv\lib\site-packages\django\core\handlers\base.py", line 204, in _get_response
    self.check_response(response, callback)
  File "C:\Users\dmitr\OneDrive\Рабочий стол\Django_hw2\venv\lib\site-packages\django\core\handlers\base.py", line 332, in check_response
    raise ValueError(
ValueError: The view modapp.views.basket didn't return an HttpResponse object. It returned None instead.
ERROR 2024-03-22 23:50:03,414 basehttp 6240 11260 "GET /user/2/ HTTP/1.1" 500 67851
INFO 2024-03-22 23:51:47,139 basehttp 6240 11260 "GET /index/ HTTP/1.1" 200 736
WARNING 2024-03-22 23:51:54,353 log 6240 11260 Not Found: /index/user_sorted/
WARNING 2024-03-22 23:51:54,353 basehttp 6240 11260 "GET /index/user_sorted/ HTTP/1.1" 404 2871
WARNING 2024-03-22 23:52:00,048 log 6240 11260 Not Found: /index/user_sorted/1
WARNING 2024-03-22 23:52:00,048 basehttp 6240 11260 "GET /index/user_sorted/1 HTTP/1.1" 404 2874
WARNING 2024-03-22 23:52:04,728 log 6240 11260 Not Found: /index/user_sorted/1/2/3
WARNING 2024-03-22 23:52:04,729 basehttp 6240 11260 "GET /index/user_sorted/1/2/3 HTTP/1.1" 404 2886
WARNING 2024-03-22 23:52:26,219 log 6240 11260 Not Found: /index/user_sorted/1/2/
WARNING 2024-03-22 23:52:26,220 basehttp 6240 11260 "GET /index/user_sorted/1/2/ HTTP/1.1" 404 2883
WARNING 2024-03-22 23:52:30,578 log 6240 11260 Not Found: /index/user_sorted/1
WARNING 2024-03-22 23:52:30,578 basehttp 6240 11260 "GET /index/user_sorted/1 HTTP/1.1" 404 2874
INFO 2024-03-22 23:52:43,707 basehttp 6240 11260 "GET /index/ HTTP/1.1" 200 736
INFO 2024-03-22 23:52:45,475 basehttp 6240 11260 "GET / HTTP/1.1" 200 736
WARNING 2024-03-22 23:52:52,576 log 6240 11260 Not Found: /user_sorted
WARNING 2024-03-22 23:52:52,576 basehttp 6240 11260 "GET /user_sorted HTTP/1.1" 404 2850
WARNING 2024-03-22 23:53:02,574 log 6240 11260 Not Found: /user_sorted/3
WARNING 2024-03-22 23:53:02,575 basehttp 6240 11260 "GET /user_sorted/3 HTTP/1.1" 404 2856
INFO 2024-03-22 23:53:09,958 basehttp 6240 11260 "GET /user_sorted/3/3 HTTP/1.1" 301 0
ERROR 2024-03-22 23:53:09,986 log 6240 14972 Internal Server Error: /user_sorted/3/3/
Traceback (most recent call last):
  File "C:\Users\dmitr\OneDrive\Рабочий стол\Django_hw2\venv\lib\site-packages\django\core\handlers\exception.py", line 55, in inner
    response = get_response(request)
  File "C:\Users\dmitr\OneDrive\Рабочий стол\Django_hw2\venv\lib\site-packages\django\core\handlers\base.py", line 197, in _get_response
    response = wrapped_callback(request, *callback_args, **callback_kwargs)
  File "C:\Users\dmitr\OneDrive\Рабочий стол\Django_hw2\modelsapp\modapp\views.py", line 22, in sorted_basket
    now = datetime.datetime.now()
AttributeError: type object 'datetime.datetime' has no attribute 'datetime'
ERROR 2024-03-22 23:53:09,987 basehttp 6240 14972 "GET /user_sorted/3/3/ HTTP/1.1" 500 67823
INFO 2024-03-22 23:54:57,778 autoreload 6240 5812 C:\Users\dmitr\OneDrive\Рабочий стол\Django_hw2\modelsapp\modapp\views.py changed, reloading.
INFO 2024-03-22 23:55:04,518 autoreload 16072 2912 Watching for file changes with StatReloader
INFO 2024-03-22 23:55:06,455 basehttp 16072 10580 "GET / HTTP/1.1" 200 736
INFO 2024-03-22 23:55:17,154 basehttp 16072 10580 "GET /user_sorted/2/3 HTTP/1.1" 301 0
INFO 2024-03-22 23:55:17,169 basehttp 16072 14684 "GET /user_sorted/2/3/ HTTP/1.1" 200 254
INFO 2024-03-22 23:55:29,535 basehttp 16072 14684 "GET /user_sorted/1/3/ HTTP/1.1" 200 264
WARNING 2024-03-22 23:55:42,352 log 16072 14684 Not Found: /user/1/3/
WARNING 2024-03-22 23:55:42,352 basehttp 16072 14684 "GET /user/1/3/ HTTP/1.1" 404 2844
WARNING 2024-03-22 23:55:45,879 log 16072 14684 Not Found: /user/1/3/3
WARNING 2024-03-22 23:55:45,880 basehttp 16072 14684 "GET /user/1/3/3 HTTP/1.1" 404 2847
INFO 2024-03-22 23:55:49,503 basehttp 16072 14684 "GET /user/1 HTTP/1.1" 301 0
ERROR 2024-03-22 23:55:49,541 log 16072 12280 Internal Server Error: /user/1/
Traceback (most recent call last):
  File "C:\Users\dmitr\OneDrive\Рабочий стол\Django_hw2\venv\lib\site-packages\django\core\handlers\exception.py", line 55, in inner
    response = get_response(request)
  File "C:\Users\dmitr\OneDrive\Рабочий стол\Django_hw2\venv\lib\site-packages\django\core\handlers\base.py", line 204, in _get_response
    self.check_response(response, callback)
  File "C:\Users\dmitr\OneDrive\Рабочий стол\Django_hw2\venv\lib\site-packages\django\core\handlers\base.py", line 332, in check_response
    raise ValueError(
ValueError: The view modapp.views.basket didn't return an HttpResponse object. It returned None instead.
ERROR 2024-03-22 23:55:49,544 basehttp 16072 12280 "GET /user/1/ HTTP/1.1" 500 67851
ERROR 2024-03-23 00:00:52,317 log 16072 1512 Internal Server Error: /user/1/
Traceback (most recent call last):
  File "C:\Users\dmitr\OneDrive\Рабочий стол\Django_hw2\venv\lib\site-packages\django\core\handlers\exception.py", line 55, in inner
    response = get_response(request)
  File "C:\Users\dmitr\OneDrive\Рабочий стол\Django_hw2\venv\lib\site-packages\django\core\handlers\base.py", line 204, in _get_response
    self.check_response(response, callback)
  File "C:\Users\dmitr\OneDrive\Рабочий стол\Django_hw2\venv\lib\site-packages\django\core\handlers\base.py", line 332, in check_response
    raise ValueError(
ValueError: The view modapp.views.basket didn't return an HttpResponse object. It returned None instead.
ERROR 2024-03-23 00:00:52,319 basehttp 16072 1512 "GET /user/1/ HTTP/1.1" 500 67988
WARNING 2024-03-23 00:00:56,328 log 16072 1512 Not Found: /user/1/2
WARNING 2024-03-23 00:00:56,328 basehttp 16072 1512 "GET /user/1/2 HTTP/1.1" 404 2841
ERROR 2024-03-23 00:00:59,043 log 16072 1512 Internal Server Error: /user/1/
Traceback (most recent call last):
  File "C:\Users\dmitr\OneDrive\Рабочий стол\Django_hw2\venv\lib\site-packages\django\core\handlers\exception.py", line 55, in inner
    response = get_response(request)
  File "C:\Users\dmitr\OneDrive\Рабочий стол\Django_hw2\venv\lib\site-packages\django\core\handlers\base.py", line 204, in _get_response
    self.check_response(response, callback)
  File "C:\Users\dmitr\OneDrive\Рабочий стол\Django_hw2\venv\lib\site-packages\django\core\handlers\base.py", line 332, in check_response
    raise ValueError(
ValueError: The view modapp.views.basket didn't return an HttpResponse object. It returned None instead.
ERROR 2024-03-23 00:00:59,045 basehttp 16072 1512 "GET /user/1/ HTTP/1.1" 500 67851
WARNING 2024-03-23 00:02:50,299 log 16072 1512 Not Found: /user
WARNING 2024-03-23 00:02:50,299 basehttp 16072 1512 "GET /user HTTP/1.1" 404 2829
ERROR 2024-03-23 00:02:55,995 log 16072 1512 Internal Server Error: /user/2/
Traceback (most recent call last):
  File "C:\Users\dmitr\OneDrive\Рабочий стол\Django_hw2\venv\lib\site-packages\django\core\handlers\exception.py", line 55, in inner
    response = get_response(request)
  File "C:\Users\dmitr\OneDrive\Рабочий стол\Django_hw2\venv\lib\site-packages\django\core\handlers\base.py", line 204, in _get_response
    self.check_response(response, callback)
  File "C:\Users\dmitr\OneDrive\Рабочий стол\Django_hw2\venv\lib\site-packages\django\core\handlers\base.py", line 332, in check_response
    raise ValueError(
ValueError: The view modapp.views.basket didn't return an HttpResponse object. It returned None instead.
ERROR 2024-03-23 00:02:55,996 basehttp 16072 1512 "GET /user/2/ HTTP/1.1" 500 67851
WARNING 2024-03-23 00:03:52,478 log 16072 1512 Not Found: /user/2/2/3
WARNING 2024-03-23 00:03:52,479 basehttp 16072 1512 "GET /user/2/2/3 HTTP/1.1" 404 2847
WARNING 2024-03-23 00:03:55,696 log 16072 1512 Not Found: /user/2/2/3/4
WARNING 2024-03-23 00:03:55,696 basehttp 16072 1512 "GET /user/2/2/3/4 HTTP/1.1" 404 2853
WARNING 2024-03-23 00:04:00,880 log 16072 1512 Not Found: /user/2/2/2013
WARNING 2024-03-23 00:04:00,881 basehttp 16072 1512 "GET /user/2/2/2013 HTTP/1.1" 404 2856
WARNING 2024-03-23 00:04:13,787 log 16072 1512 Not Found: /user/
WARNING 2024-03-23 00:04:13,787 basehttp 16072 1512 "GET /user/ HTTP/1.1" 404 2832
WARNING 2024-03-23 00:04:49,158 log 16072 1512 Not Found: /user
WARNING 2024-03-23 00:04:49,158 basehttp 16072 1512 "GET /user HTTP/1.1" 404 2829
ERROR 2024-03-23 00:04:52,731 log 16072 1512 Internal Server Error: /user/3/
Traceback (most recent call last):
  File "C:\Users\dmitr\OneDrive\Рабочий стол\Django_hw2\venv\lib\site-packages\django\core\handlers\exception.py", line 55, in inner
    response = get_response(request)
  File "C:\Users\dmitr\OneDrive\Рабочий стол\Django_hw2\venv\lib\site-packages\django\core\handlers\base.py", line 204, in _get_response
    self.check_response(response, callback)
  File "C:\Users\dmitr\OneDrive\Рабочий стол\Django_hw2\venv\lib\site-packages\django\core\handlers\base.py", line 332, in check_response
    raise ValueError(
ValueError: The view modapp.views.basket didn't return an HttpResponse object. It returned None instead.
ERROR 2024-03-23 00:04:52,732 basehttp 16072 1512 "GET /user/3/ HTTP/1.1" 500 67851
WARNING 2024-03-23 00:04:58,893 log 16072 1512 Not Found: /user/3/3
WARNING 2024-03-23 00:04:58,893 basehttp 16072 1512 "GET /user/3/3 HTTP/1.1" 404 2841
WARNING 2024-03-23 00:05:01,821 log 16072 1512 Not Found: /user/3/3/3
WARNING 2024-03-23 00:05:01,822 basehttp 16072 1512 "GET /user/3/3/3 HTTP/1.1" 404 2847
INFO 2024-03-23 00:06:28,041 autoreload 16072 2912 C:\Users\dmitr\OneDrive\Рабочий стол\Django_hw2\modelsapp\modapp\views.py changed, reloading.
INFO 2024-03-23 00:06:52,642 autoreload 1292 16804 Watching for file changes with StatReloader
WARNING 2024-03-23 00:06:52,833 log 1292 12228 Not Found: /user/3/3/3
WARNING 2024-03-23 00:06:52,833 basehttp 1292 12228 "GET /user/3/3/3 HTTP/1.1" 404 2847
INFO 2024-03-23 00:06:58,998 basehttp 1292 12228 "GET / HTTP/1.1" 200 736
INFO 2024-03-23 00:07:01,357 basehttp 1292 12228 "GET / HTTP/1.1" 200 736
INFO 2024-03-23 00:07:03,787 basehttp 1292 12228 "GET / HTTP/1.1" 200 736
INFO 2024-03-23 00:07:14,738 basehttp 1292 12228 "GET /user_sorted/3/3/ HTTP/1.1" 200 254
WARNING 2024-03-23 00:07:22,478 log 1292 12228 Not Found: /user/3/3/
WARNING 2024-03-23 00:07:22,478 basehttp 1292 12228 "GET /user/3/3/ HTTP/1.1" 404 2844
INFO 2024-03-23 00:07:26,117 basehttp 1292 12228 "GET /user/3/ HTTP/1.1" 200 199
INFO 2024-03-23 00:17:23,256 autoreload 1604 13064 Watching for file changes with StatReloader
INFO 2024-03-23 00:17:25,683 basehttp 1604 3116 "GET / HTTP/1.1" 200 736
INFO 2024-03-23 00:17:30,686 basehttp 1604 3116 "GET /user/3/ HTTP/1.1" 200 199
INFO 2024-03-23 00:17:33,724 basehttp 1604 3116 "GET /user/31 HTTP/1.1" 301 0
INFO 2024-03-23 00:17:33,739 basehttp 1604 10960 "GET /user/31/ HTTP/1.1" 200 191
INFO 2024-03-23 00:17:37,883 basehttp 1604 10960 "GET /user/1/ HTTP/1.1" 200 209
INFO 2024-03-23 00:19:51,450 basehttp 1604 10960 "GET /user/1/ HTTP/1.1" 200 361
INFO 2024-03-23 00:20:04,964 basehttp 1604 10960 "GET /user/2/ HTTP/1.1" 200 349
INFO 2024-03-23 00:21:58,669 basehttp 1604 10960 "GET /user/2/ HTTP/1.1" 200 437
INFO 2024-03-23 00:22:11,225 basehttp 1604 10960 "GET /user/1/ HTTP/1.1" 200 450
INFO 2024-03-23 00:24:14,469 basehttp 1604 10960 "GET /user/3/ HTTP/1.1" 200 349
INFO 2024-03-23 00:24:20,253 basehttp 1604 10960 "GET /user/2/ HTTP/1.1" 200 437
WARNING 2024-03-23 00:25:56,823 log 1604 10960 Not Found: /user_sorted/2/3/1
WARNING 2024-03-23 00:25:56,824 basehttp 1604 10960 "GET /user_sorted/2/3/1 HTTP/1.1" 404 2868
WARNING 2024-03-23 00:26:02,932 log 1604 10960 Not Found: /user_sorted/1
WARNING 2024-03-23 00:26:02,933 basehttp 1604 10960 "GET /user_sorted/1 HTTP/1.1" 404 2856
INFO 2024-03-23 00:26:07,079 basehttp 1604 10960 "GET /user_sorted/1/2 HTTP/1.1" 301 0
INFO 2024-03-23 00:26:07,097 basehttp 1604 16204 "GET /user_sorted/1/2/ HTTP/1.1" 200 264
INFO 2024-03-23 00:26:16,946 basehttp 1604 16204 "GET /user_sorted/1/3/ HTTP/1.1" 200 264
INFO 2024-03-23 00:26:20,554 basehttp 1604 16204 "GET /user_sorted/1/1/ HTTP/1.1" 200 264
INFO 2024-03-23 00:26:28,315 basehttp 1604 16204 "GET /user_sorted/2/1/ HTTP/1.1" 200 254
WARNING 2024-03-23 00:26:37,407 log 1604 14976 Not Found: /favicon.ico
WARNING 2024-03-23 00:26:37,407 basehttp 1604 14976 "GET /favicon.ico HTTP/1.1" 404 2850
INFO 2024-03-27 22:47:19,720 autoreload 5620 13700 Watching for file changes with StatReloader
INFO 2024-03-27 22:50:43,725 autoreload 14812 1512 Watching for file changes with StatReloader
INFO 2024-03-27 22:51:31,452 autoreload 14812 1512 C:\Users\dmitr\OneDrive\Рабочий стол\Django_hw2\modelsapp\modapp\views.py changed, reloading.
INFO 2024-03-27 22:51:31,808 autoreload 6716 14852 Watching for file changes with StatReloader
INFO 2024-03-27 22:51:37,006 autoreload 6716 14852 C:\Users\dmitr\OneDrive\Рабочий стол\Django_hw2\modelsapp\modapp\views.py changed, reloading.
INFO 2024-03-27 22:52:01,735 autoreload 13360 10624 Watching for file changes with StatReloader
INFO 2024-03-27 22:53:39,116 autoreload 13360 10624 C:\Users\dmitr\OneDrive\Рабочий стол\Django_hw2\modelsapp\formsapp\forms.py changed, reloading.
INFO 2024-03-27 22:54:22,708 autoreload 1376 14684 Watching for file changes with StatReloader
INFO 2024-03-27 23:06:16,468 autoreload 10232 7960 Watching for file changes with StatReloader
INFO 2024-03-27 23:07:26,662 autoreload 10232 7960 C:\Users\dmitr\OneDrive\Рабочий стол\Django_hw2\modelsapp\modelsapp\settings.py changed, reloading.
INFO 2024-03-27 23:07:27,005 autoreload 13664 11752 Watching for file changes with StatReloader
INFO 2024-03-27 23:07:28,256 autoreload 13664 11752 C:\Users\dmitr\OneDrive\Рабочий стол\Django_hw2\modelsapp\modelsapp\settings.py changed, reloading.
INFO 2024-03-27 23:07:28,611 autoreload 8024 14108 Watching for file changes with StatReloader
INFO 2024-03-27 23:08:57,996 autoreload 8096 5516 Watching for file changes with StatReloader
INFO 2024-03-27 23:16:54,133 autoreload 13944 2148 Watching for file changes with StatReloader
INFO 2024-03-27 23:18:31,693 autoreload 13944 2148 C:\Users\dmitr\OneDrive\Рабочий стол\Django_hw2\modelsapp\formsapp\forms.py changed, reloading.
INFO 2024-03-27 23:18:32,065 autoreload 8040 11644 Watching for file changes with StatReloader
INFO 2024-03-27 23:18:55,254 basehttp 8040 15368 "GET / HTTP/1.1" 200 736
WARNING 2024-03-27 23:18:55,272 log 8040 15376 Not Found: /favicon.ico
WARNING 2024-03-27 23:18:55,272 basehttp 8040 15376 "GET /favicon.ico HTTP/1.1" 404 3058
WARNING 2024-03-27 23:18:55,372 log 8040 15368 Not Found: /favicon.ico
WARNING 2024-03-27 23:18:55,373 basehttp 8040 15368 "GET /favicon.ico HTTP/1.1" 404 3058
INFO 2024-03-27 23:19:20,282 basehttp 8040 16160 "GET /index/ HTTP/1.1" 200 736
INFO 2024-03-27 23:19:21,531 basehttp 8040 16160 "GET /index/ HTTP/1.1" 200 736
WARNING 2024-03-27 23:19:35,835 log 8040 16160 Not Found: /index/product_update/2
WARNING 2024-03-27 23:19:35,835 basehttp 8040 16160 "GET /index/product_update/2 HTTP/1.1" 404 3091
WARNING 2024-03-27 23:19:57,903 log 8040 16160 Not Found: /index/product_update/2/2/2
WARNING 2024-03-27 23:19:57,903 basehttp 8040 16160 "GET /index/product_update/2/2/2 HTTP/1.1" 404 3103
WARNING 2024-03-27 23:20:02,832 log 8040 16160 Not Found: /index/product_update/1
WARNING 2024-03-27 23:20:02,832 basehttp 8040 16160 "GET /index/product_update/1 HTTP/1.1" 404 3091
INFO 2024-03-27 23:20:13,168 basehttp 8040 16160 "GET /index/ HTTP/1.1" 200 736
INFO 2024-03-27 23:20:14,369 basehttp 8040 16160 "GET /hw3/ HTTP/1.1" 200 736
INFO 2024-03-27 23:20:15,887 basehttp 8040 16160 "GET /hw4 HTTP/1.1" 301 0
INFO 2024-03-27 23:20:15,904 basehttp 8040 16240 "GET /hw4/ HTTP/1.1" 200 393
INFO 2024-03-27 23:20:32,995 basehttp 8040 13556 "GET /hw4/product_update/2 HTTP/1.1" 200 1243
WARNING 2024-03-27 23:23:42,784 log 8040 13556 Not Found: /myformapp/user/add/
WARNING 2024-03-27 23:23:42,784 basehttp 8040 13556 "GET /myformapp/user/add/ HTTP/1.1" 404 3082
INFO 2024-03-27 23:24:15,877 basehttp 8040 13556 "POST /hw4/product_update/2 HTTP/1.1" 200 1321
INFO 2024-03-27 23:26:11,754 basehttp 8040 13556 "POST /hw4/product_update/2 HTTP/1.1" 200 1318
INFO 2024-03-27 23:27:45,361 basehttp 8040 13556 "POST /hw4/product_update/2 HTTP/1.1" 200 1301
INFO 2024-03-27 23:29:45,417 basehttp 8040 13556 "POST /hw4/product_update/2 HTTP/1.1" 200 1304
INFO 2024-03-27 23:30:58,379 basehttp 8040 13556 "POST /hw4/product_update/2 HTTP/1.1" 200 1304
INFO 2024-03-27 23:34:06,241 autoreload 17100 17104 Watching for file changes with StatReloader
INFO 2024-03-27 23:34:10,978 basehttp 17100 17672 "POST /hw4/product_update/2 HTTP/1.1" 200 1303
WARNING 2024-03-27 23:34:33,864 log 17100 15060 Not Found: /favicon.ico
WARNING 2024-03-27 23:34:33,865 basehttp 17100 15060 "GET /favicon.ico HTTP/1.1" 404 3058
